Workbook
Name Slicer_Region: #N/A

Sheet Transactions
A1: Transaction ID | B1: Date | C1: Product ID | D1: Product Name | E1: Category | F1: Quantity Sold | G1: Unit Price | H1: Customer ID | I1: State | J1: Region | K1: Total Sales | L1: Student ID | M1: Unit Price | N1: Blank Count
A2: 1001 | B2: 44204.053 | C2: 14723 | D2: Camping Tent | E2: Sports & Outdoors | F2: 12 | G2: 320.27728 | H2: 125542 | I2: North Dakota | J2: =VLOOKUP(I2, 'State-Regions'!A:B, 2, FALSE) -> Midwest | K2: =G2*F2 -> 3843.3274 | L2: JOSZIM1500 | M2: 320.27728 | N2: =COUNTBLANK(A1:L306) -> 0
A3: 1002 | B3: 44327.721 | C3: 13542 | D3: UNKNOWN | E3: Electronics | F3: 9 | G3: 58.777695 | H3: 106222 | I3: Minnesota | J3: =VLOOKUP(I3, 'State-Regions'!A:B, 2, FALSE) -> Midwest | K3: =G3*F3 -> 528.99925 | L3: JOSZIM1500 | M3: 58.777695
A4: 1003 | B4: 44541.66 | C4: 14097 | D4: Yoga Mat | E4: Sports & Outdoors | F4: 18 | G4: 48.655521 | H4: 124344 | I4: Delaware | J4: =VLOOKUP(I4, 'State-Regions'!A:B, 2, FALSE) -> South | K4: =G4*F4 -> 875.79937 | L4: JOSZIM1500 | M4: 48.655521
A5: 1004 | B5: 44270.69 | C5: 15350 | D5: Fitness Tracker | E5: Electronics | F5: 6 | G5: 147.62746 | H5: 101349 | I5: North Carolina | J5: =VLOOKUP(I5, 'State-Regions'!A:B, 2, FALSE) -> South | K5: =G5*F5 -> 885.76476 | L5: JOSZIM1500 | M5: 147.62746
A6: 1005 | B6: 44208.019 | C6: 10847 | D6: Wall Clock | E6: Sports & Outdoors | F6: 5 | G6: 46.070653 | H6: 192968 | I6: Massachusetts | J6: =VLOOKUP(I6, 'State-Regions'!A:B, 2, FALSE) -> Northeast | K6: =G6*F6 -> 230.35327 | L6: JOSZIM1500 | M6: 46.070653
A7: 1006 | B7: 44226.232 | C7: 19023 | D7: Kitchen Knife Set | E7: Sports & Outdoors | F7: 7 | G7: 435.66014 | H7: 113896 | I7: Kentucky | J7: =VLOOKUP(I7, 'State-Regions'!A:B, 2, FALSE) -> South | K7: =G7*F7 -> 3049.621 | L7: JOSZIM1500 | M7: 435.66014
A8: 1007 | B8: 44361.363 | C8: 16025 | D8: Thermal Flask | E8: Home Furnishing | F8: 5 | G8: 296.26549 | H8: 109358 | I8: Idaho | J8: =VLOOKUP(I8, 'State-Regions'!A:B, 2, FALSE) -> West | K8: =G8*F8 -> 1481.3275 | L8: JOSZIM1500 | M8: 296.26549
A9: 1008 | B9: 44460.148 | C9: 12630 | D9: Blender | E9: Sports & Outdoors | F9: 4 | G9: 224.39792 | H9: 165288 | I9: Mississippi | J9: =VLOOKUP(I9, 'State-Regions'!A:B, 2, FALSE) -> South | K9: =G9*F9 -> 897.59168 | L9: JOSZIM1500 | M9: 224.39792
A10: 1009 | B10: 44343.368 | C10: 18791 | D10: Fitness Tracker | E10: Sports & Outdoors | F10: 1 | G10: 227.93767 | H10: 127368 | I10: Arkansas | J10: =VLOOKUP(I10, 'State-Regions'!A:B, 2, FALSE) -> South | K10: =G10*F10 -> 227.93767 | L10: JOSZIM1500 | M10: 227.93767
A11: 1010 | B11: 44506.335 | C11: 12804 | D11: Bed Sheet Set | E11: Home & Kitchen | F11: 6 | G11: 398.68691 | H11: 171280 | I11: Illinois | J11: =VLOOKUP(I11, 'State-Regions'!A:B, 2, FALSE) -> Midwest | K11: =G11*F11 -> 2392.1215 | L11: JOSZIM1500 | M11: 398.68691
A12: 1011 | B12: 44290.759 | C12: 14203 | D12: Blender | E12: Home & Kitchen | F12: 13 | G12: 344.71229 | H12: 155331 | I12: Indiana | J12: =VLOOKUP(I12, 'State-Regions'!A:B, 2, FALSE) -> Midwest | K12: =G12*F12 -> 4481.2597 | L12: JOSZIM1500 | M12: 344.71229
A13: 1012 | B13: 44316.153 | C13: 19620 | D13: Running Shoes | E13: Home & Kitchen | F13: 11 | G13: 199.69271 | H13: 178997 | I13: Alaska | J13: =VLOOKUP(I13, 'State-Regions'!A:B, 2, FALSE) -> West | K13: =G13*F13 -> 2196.6198 | L13: JOSZIM1500 | M13: 199.69271
A14: 1013 | B14: 44420.752 | C14: 12024 | D14: Coffee Maker | E14: Home Furnishing | F14: 7 | G14: 364.39779 | H14: 163107 | I14: Vermont | J14: =VLOOKUP(I14, 'State-Regions'!A:B, 2, FALSE) -> Northeast | K14: =G14*F14 -> 2550.7845 | L14: JOSZIM1500 | M14: 364.39779
... A22: 1021 | B22: 44546.925 | C22: 12546 | D22: Wall Clock | E22: Sports & Outdoors | F22: 13 | G22: 406.19936 | H22: 193743 | I22: South Carolina | J22: =VLOOKUP(I22, 'State-Regions'!A:B, 2, FALSE) -> South | K22: =G22*F22 -> 5280.5917 | L22: JOSZIM1500 | M22: 406.19936
A23: 1022 | B23: 44548.304 | C23: 16390 | D23: Waterproof Backpack | E23: Sports & Outdoors | F23: 4 | G23: =AVERAGE(M:M) -> 262.936 | H23: 132352 | I23: Virginia | J23: =VLOOKUP(I23, 'State-Regions'!A:B, 2, FALSE) -> South | K23: =G23*F23 -> 1051.744 | L23: JOSZIM1500
A24: 1023 | B24: 44327.529 | C24: 19579 | D24: Non-stick Pan | E24: Home & Kitchen | F24: 17 | G24: 39.729112 | H24: 195024 | I24: Oregon | J24: =VLOOKUP(I24, 'State-Regions'!A:B, 2, FALSE) -> West | K24: =G24*F24 -> 675.3949 | L24: JOSZIM1500 | M24: 39.729112
A25: 1024 | B25: 44270.633 | C25: 13310 | D25: Coffee Maker | E25: Home & Kitchen | F25: 1 | G25: 125.99245 | H25: 165464 | I25: Georgia | J25: =VLOOKUP(I25, 'State-Regions'!A:B, 2, FALSE) -> South | K25: =G25*F25 -> 125.99245 | L25: JOSZIM1500 | M25: 125.99245
A26: 1025 | B26: 44335.883 | C26: 18981 | D26: Bluetooth Headphones | E26: Electronics | F26: 11 | G26: 312.97293 | H26: 156199 | I26: Rhode Island | J26: =VLOOKUP(I26, 'State-Regions'!A:B, 2, FALSE) -> Northeast | K26: =G26*F26 -> 3442.7023 | L26: JOSZIM1500 | M26: 312.97293
A27: 1026 | B27: 44319.026 | C27: 12167 | D27: Microwave Oven | E27: Electronics | F27: 2 | G27: 380.06513 | H27: 148535 | I27: Mississippi | J27: =VLOOKUP(I27, 'State-Regions'!A:B, 2, FALSE) -> South | K27: =G27*F27 -> 760.13026 | L27: JOSZIM1500 | M27: 380.06513
A28: 1027 | B28: 44519.385 | C28: 16649 | D28: Ergonomic Chair | E28: Home & Kitchen | F28: 8 | G28: 225.38125 | H28: 147646 | I28: Ohio | J28: =VLOOKUP(I28, 'State-Regions'!A:B, 2, FALSE) -> Midwest | K28: =G28*F28 -> 1803.05 | L28: JOSZIM1500 | M28: 225.38125
A29: 1028 | B29: 44502.323 | C29: 10652 | D29: Smart Watch | E29: Sports & Outdoors | F29: 16 | G29: 482.6501 | H29: 138257 | I29: Virginia | J29: =VLOOKUP(I29, 'State-Regions'!A:B, 2, FALSE) -> South | K29: =G29*F29 -> 7722.4016 | L29: JOSZIM1500 | M29: 482.6501
A30: 1029 | B30: 44287.754 | C30: 11739 | D30: UNKNOWN | E30: Sports & Outdoors | F30: 18 | G30: 486.18206 | H30: 178221 | I30: Wyoming | J30: =VLOOKUP(I30, 'State-Regions'!A:B, 2, FALSE) -> West | K30: =G30*F30 -> 8751.2772 | L30: JOSZIM1500 | M30: 486.18206
A31: 1030 | B31: 44556.019 | C31: 13369 | D31: UNKNOWN | E31: Home Furnishing | F31: 10 | G31: 465.80612 | H31: 136530 | I31: South Dakota | J31: =VLOOKUP(I31, 'State-Regions'!A:B, 2, FALSE) -> Midwest | K31: =G31*F31 -> 4658.0612 | L31: JOSZIM1500 | M31: 465.80612
A32: 1031 | B32: 44287.367 | C32: 19165 | D32: Coffee Maker | E32: Electronics | F32: 9 | G32: 262.6261 | H32: 114065 | I32: Connecticut | J32: =VLOOKUP(I32, 'State-Regions'!A:B, 2, FALSE) -> Northeast | K32: =G32*F32 -> 2363.6349 | L32: JOSZIM1500 | M32: 262.6261
A33: 1032 | B33: 44198.573 | C33: 12599 | D33: Running Shoes | E33: Electronics | F33: 8 | G33: 49.300465 | H33: 147619 | I33: Montana | J33: =VLOOKUP(I33, 'State-Regions'!A:B, 2, FALSE) -> West | K33: =G33*F33 -> 394.40372 | L33: JOSZIM1500 | M33: 49.300465
A34: 1033 | B34: 44511.767 | C34: 13157 | D34: Smart Watch | E34: Electronics | F34: 4 | G34: 270.42648 | H34: 106340 | I34: Maryland | J34: =VLOOKUP(I34, 'State-Regions'!A:B, 2, FALSE) -> South | K34: =G34*F34 -> 1081.7059 | L34: JOSZIM1500 | M34: 270.42648
A35: 1034 | B35: 44311.099 | C35: 16713 | D35: Ergonomic Chair | E35: Home & Kitchen | F35: 19 | G35: 227.9346 | H35: 136505 | I35: Missouri | J35: =VLOOKUP(I35, 'State-Regions'!A:B, 2, FALSE) -> Midwest | K35: =G35*F35 -> 4330.7573 | L35: JOSZIM1500 | M35: 227.9346
... A47: 1046 | B47: 44314.956 | C47: 13032 | D47: Wall Clock | E47: Sports & Outdoors | F47: 17 | G47: 329.98245 | H47: 136278 | I47: Illinois | J47: =VLOOKUP(I47, 'State-Regions'!A:B, 2, FALSE) -> Midwest | K47: =G47*F47 -> 5609.7016 | L47: JOSZIM1500 | M47: 329.98245
A48: 1047 | B48: 44356.474 | C48: 18353 | D48: non-stick pan | E48: Home Furnishing | F48: 16 | G48: =AVERAGE(M:M) -> 262.936 | H48: 116117 | I48: Louisiana | J48: =VLOOKUP(I48, 'State-Regions'!A:B, 2, FALSE) -> South | K48: =G48*F48 -> 4206.9759 | L48: JOSZIM1500
A49: 1048 | B49: 44417.162 | C49: 16639 | D49: UNKNOWN | E49: Electronics | F49: 11 | G49: 357.87867 | H49: 119419 | I49: North Dakota | J49: =VLOOKUP(I49, 'State-Regions'!A:B, 2, FALSE) -> Midwest | K49: =G49*F49 -> 3936.6654 | L49: JOSZIM1500 | M49: 357.87867
A50: 1049 | B50: 44362.038 | C50: 13484 | D50: Waterproof Backpack | E50: Home Furnishing | F50: 6 | G50: 114.2794 | H50: 150804 | I50: Illinois | J50: =VLOOKUP(I50, 'State-Regions'!A:B, 2, FALSE) -> Midwest | K50: =G50*F50 -> 685.67639 | L50: JOSZIM1500 | M50: 114.2794
A51: 1050 | B51: 44488.784 | C51: 10931 | D51: Blender | E51: Home Furnishing | F51: 3 | G51: 51.909427 | H51: 172015 | I51: New Jersey | J51: =VLOOKUP(I51, 'State-Regions'!A:B, 2, FALSE) -> Northeast | K51: =G51*F51 -> 155.72828 | L51: JOSZIM1500 | M51: 51.909427
A52: 1051 | B52: 44457.686 | C52: 14515 | D52: Microwave Oven | E52: Sports & Outdoors | F52: 15 | G52: 391.66327 | H52: 192075 | I52: Missouri | J52: =VLOOKUP(I52, 'State-Regions'!A:B, 2, FALSE) -> Midwest | K52: =G52*F52 -> 5874.949 | L52: JOSZIM1500 | M52: 391.66327
A53: 1052 | B53: 44426.515 | C53: 12250 | D53: Portable Charger | E53: Home Furnishing | F53: 6 | G53: 72.887978 | H53: 119058 | I53: Arizona | J53: =VLOOKUP(I53, 'State-Regions'!A:B, 2, FALSE) -> West | K53: =G53*F53 -> 437.32787 | L53: JOSZIM1500 | M53: 72.887978
A54: 1053 | B54: 44372.183 | C54: 12034 | D54: Microwave Oven | E54: Sports & Outdoors | F54: 1 | G54: 346.45468 | H54: 191384 | I54: Connecticut | J54: =VLOOKUP(I54, 'State-Regions'!A:B, 2, FALSE) -> Northeast | K54: =G54*F54 -> 346.45468 | L54: JOSZIM1500 | M54: 346.45468
A55: 1054 | B55: 44544.401 | C55: 16168 | D55: Running Shoes | E55: Sports & Outdoors | F55: 6 | G55: 439.27828 | H55: 175179 | I55: Hawaii | J55: =VLOOKUP(I55, 'State-Regions'!A:B, 2, FALSE) -> West | K55: =G55*F55 -> 2635.6697 | L55: JOSZIM1500 | M55: 439.27828
A56: 1055 | B56: 44273.197 | C56: 15282 | D56: Microwave Oven | E56: Home & Kitchen | F56: 4 | G56: 428.56881 | H56: 112073 | I56: New Hampshire | J56: =VLOOKUP(I56, 'State-Regions'!A:B, 2, FALSE) -> Northeast | K56: =G56*F56 -> 1714.2753 | L56: JOSZIM1500 | M56: 428.56881
A57: 1056 | B57: 44317.622 | C57: 14791 | D57: blender | E57: Sports & Outdoors | F57: 11 | G57: 99.506136 | H57: 153662 | I57: Washington | J57: =VLOOKUP(I57, 'State-Regions'!A:B, 2, FALSE) -> West | K57: =G57*F57 -> 1094.5675 | L57: JOSZIM1500 | M57: 99.506136
A58: 1057 | B58: 44514.626 | C58: 11873 | D58: Ergonomic Chair | E58: Electronics | F58: 15 | G58: 463.75542 | H58: 128346 | I58: Florida | J58: =VLOOKUP(I58, 'State-Regions'!A:B, 2, FALSE) -> South | K58: =G58*F58 -> 6956.3313 | L58: JOSZIM1500 | M58: 463.75542
...

Sheet State-Regions
A1: State | B1: Region
A2: Connecticut | B2: Northeast
A3: Maine | B3: Northeast
A4: Massachusetts | B4: Northeast
A5: New Hampshire | B5: Northeast
A6: New Jersey | B6: Northeast
A7: New York | B7: Northeast
A8: Pennsylvania | B8: Northeast
A9: Rhode Island | B9: Northeast
A10: Vermont | B10: Northeast
A11: Illinois | B11: Midwest
A12: Indiana | B12: Midwest
... A51: Wyoming | B51: West

Sheet Excel-Functions
A1: SUMIFS
A2: Product Name | B2: Region | C2: Total Sales | D2: StudentID
A3: Wireless Mouse | B3: Midwest | C3: =SUMIFS(Transactions!K:K, Transactions!D:D, A3, Transactions!J:J,B3) -> 21560.978 | D3: JOSZIM1500
A5: COUNTIFS
A6: High Value Sale | B6: Region | C6: Count | D6: StudentID
A7: 3000 | B7: Midwest | C7: =COUNTIFS(Transactions!K:K, ">"&A7, Transactions!J:J, B7) -> 29 | D7: JOSZIM1500
A9: AVERAGEIFS
A10: Product Name | B10: Region | C10: Average Sales | D10: StudentID
A11: Thermal Flask | B11: West | C11: =AVERAGEIFS(Transactions!K:K, Transactions!D:D, A11,Transactions!J:J, B11) -> 2192.6915 | D11: JOSZIM1500

Sheet PivotTables
A1: Sum of Total Sales | B1: Column Labels
A2: Row Labels | B2: Midwest | C2: Northeast | D2: South | E2: West | F2: Grand Total
A3: Electronics | B3: 48639.245 | C3: 36473.43 | D3: 37267.108 | E3: 43156.037 | F3: 165535.82
A4: Home & Kitchen | B4: 56082.15 | C4: 20854.722 | D4: 46297.369 | E4: 43672.997 | F4: 166907.24
A5: Home Furnishing | B5: 54876.708 | C5: 39041.618 | D5: 79348.338 | E5: 46355.244 | F5: 219621.91
A6: Sports & Outdoors | B6: 53232.958 | C6: 22010.288 | D6: 64097.926 | E6: 79041.437 | F6: 218382.61
A7: Grand Total | B7: 212831.06 | C7: 118380.06 | D7: 227010.74 | E7: 212225.71 | F7: 770447.57
B17: Row Labels | C17: Sum of Total Sales
B18: Bed Sheet Set | C18: 34812.943
B19: Blender | C19: 63848.046
B20: Bluetooth Headphones | C20: 21909.154
B21: Camping Tent | C21: 28623.175
B22: Coffee Maker | C22: 38962.106
B23: Cotton Towels | C23: 29700.49
B24: Ergonomic Chair | C24: 28848.095
B25: Fitness Tracker | C25: 26200.519
B26: Kitchen Knife Set | C26: 51754.345
B27: LED Desk Lamp | C27: 24490.027
B28: Microwave Oven | C28: 41147.063
B29: Non-stick Pan | C29: 37848.97
... B38: Grand Total | C38: 738982.67
